Workbook

Sheet Sheet1
A1: Position | B1: Abbreviation | C1: Appointment_Type_Id | D1: Chief | E1: Discipline | F1: Lower_Levels_Only
A2: Chief Referee; Data Operator; Judge | B2: CR, DO, J-S | C2: 1 | E2: 1
A3: Data Operator; Judge | B3: DO, J-S | C3: 1 | E3: 1
A4: Data Operator; Judge Singles; TS Singles | B4: DO, J-S, TS-S | C4: 1 | E4: 1
A5: Judges D/S | B5: J-DS | C5: 1 | E5: 1
A6: Judge S | B6: J-S | C6: 1 | E6: 1
A7: Judges S | B7: J-S | C7: 1 | E7: 1
A8: Judge Singles | B8: J-S | C8: 1 | E8: 1
A9: Judge Singles | B9: J-S | C9: 1 | E9: 1
A10: Judge | B10: J-S | C10: 1 | E10: 1
A11: Judge Singles; Assistant Referee | B11: J-S, DO | C11: 1 | E11: 1
A12: Judge Singles; TC Singles; Referee; TS Singles | B12: J-S, R | C12: 1 | E12: 1
A13: Judge Singles; Referee Singles | C13: 1 | E13: 1
A14: Judge Singes; Referee Singles; Data Operator | C14: 1 | E14: 1
A15: Judge Singles; TC Singles; Referee; Data Operator | C15: 1 | E15: 1
A16: Judge Singles; TS Singles; TC Singles; Data Operator | C16: 1 | E16: 1
A17: Judge Singles; Data Operator | C17: 1 | E17: 1
A18: Judges S + Data | B18: J-S/DO | C18: 1 | E18: 1
A19: Judge S+D | B19: J-SD | C19: 1 | E19: 1
A20: Judge Dance; Judge Singles | B20: J-SD | C20: 1 | E20: 1
A21: Judge Singles and Dance | B21: J-SD | C21: 1 | E21: 1
A22: Assistant Dance Referee; TC Dance; Judge Singles & Dance; Data Operator | C22: 1 | E22: 1
A23: Assistant Referee; Judge Singles; Data Operator | C23: 1 | E23: 1
A24: TC Dance; Judge Dance; Judge Singles; Referee | C24: 1 | E24: 1
A25: TC Singles; Judge Singles; Data Operator | C25: 1 | E25: 1
A26: TC Singles; Judge Singles; Referee Singles and Dance | C26: 1 | E26: 1
A27: TC Singles; Judge | B27: TC-S, J-SP | C27: 1 | E27: 1
A28: TC Singles; Referee; Judge | B28: TC-S, R, J-S | C28: 1 | E28: 1
A29: TC-S + J-S | C29: 1 | E29: 1
A30: Judges S + TC-S | C30: 1 | E30: 1
A31: TC-Singles/Judge | C31: 1 | E31: 1
A32: TC-Singles/ Judge | C32: 1 | E32: 1
A33: Judge Dance | B33: J-D | C33: 1 | E33: 4
A34: Judge Dance (senior) | B34: J-D | C34: 1 | E34: 4
A35: Judge D | B35: J-D | C35: 1 | E35: 4
A36: Judges D | B36: J-D | C36: 1 | E36: 4
A37: Judge Dance- Lower | B37: J-D (Lower) | C37: 1 | E37: 4 | F37: 1
A38: Judge Dance; TS Dance | B38: J-D, TS-D | C38: 1 | E38: 4
A39: Judges D/S | B39: J-DS | C39: 1 | E39: 4
A40: Judge S+D | B40: J-SD | C40: 1 | E40: 4
...

Sheet Sheet2
A1: Position | B1: Abbreviation
A2: Chief Referee-SYS | B2: CR | C2: =COUNTIF(Sheet1!A:A,Sheet2!A2) -> 1
A3: Assistant Referee-SYS | B3: R | C3: =COUNTIF(Sheet1!A:A,Sheet2!A3) -> 1
A4: Chief Accountant | B4: C-Acc | C4: =COUNTIF(Sheet1!A:A,Sheet2!A4) -> 1
A5: Assistant Accountant | B5: Acc | C5: =COUNTIF(Sheet1!A:A,Sheet2!A5) -> 1
A6: Chief Technical Accountant | B6: C-TA | C6: =COUNTIF(Sheet1!A:A,Sheet2!A6) -> 1
A7: Assistant Technical Accountant | B7: TA | C7: =COUNTIF(Sheet1!A:A,Sheet2!A7) -> 1
A8: Chief Music Coordinator | B8: C-M | C8: =COUNTIF(Sheet1!A:A,Sheet2!A8) -> 1
A9: Assistant Music Coordinator | B9: M | C9: =COUNTIF(Sheet1!A:A,Sheet2!A9) -> 1
A10: Music Technician | B10: MT | C10: =COUNTIF(Sheet1!A:A,Sheet2!A10) -> 1
A11: Chief Announcer | B11: C-Ann | C11: =COUNTIF(Sheet1!A:A,Sheet2!A11) -> 1
A12: Announcer | B12: Ann | C12: =COUNTIF(Sheet1!A:A,Sheet2!A12) -> 1
A13: TC-SYS | B13: TC | C13: =COUNTIF(Sheet1!A:A,Sheet2!A13) -> 1
... A34: Assistant Referee/TC-SYS | B34: R/TC | C34: =COUNTIF(Sheet1!A:A,Sheet2!A34) -> 2
