Workbook

Sheet Sheet1
AK1: 2026 Easterns | AN1: 2026 Midwesterns | AQ1: 2026 Pacific Coast | AT1: 2025 Easterns | AW1: 2025 Midwesterns | AZ1: 2025 Pacific Coast | BC1: 2024 Easterns | BF1: 2024 Midwesterns | BI1: 2024 Pacific Coast | BL1: 2023 Easterns | BO1: 2023 MidPac | BR1: 2022 Easterns | BU1: 2022 MidPac | BX1: 2020 Easterns | CA1: 2020 MidPac | CD1: 2019 Easterns | CG1: 2019 MidPac | CJ1: 2018 Easterns | CM1: 2018 MidPac | CP1: 2017 Easterns | CS1: 2017 MidPac | CV1: 2016 Easterns | CY1: 2016 MidPac | DB1: 2015 Eastern Synchronized Sectional Championships | DE1: 2015 MidPac Synchronized Sectional Championships
AK2: Assigned Official | AL2: Position | AN2: Assigned Official | AO2: Position | AQ2: Assigned Official | AR2: Position | AT2: Assigned Official | AU2: Position | AW2: Assigned Official | AX2: Position | AZ2: Assigned Official | BA2: Position | BC2: Assigned Official | BD2: Position | BF2: Assigned Official | BG2: Position | BI2: Assigned Official | BJ2: Position | BL2: Assigned Official | BM2: Position | BO2: Assigned Official | BP2: Position | BR2: Assigned Official | BS2: Position | BU2: Assigned Official | BV2: Position | BX2: Assigned Official | BY2: Position | CA2: Assigned Official | CB2: Position | CD2: Assigned Official | CE2: Position | CG2: Assigned Official | CH2: Position | CJ2: Assigned Official | CK2: Position | CM2: Assigned Official | CN2: Position | CP2: Assigned Official | CQ2: Position | CS2: Assigned Official | CT2: Position | CV2: Assigned Official | CW2: Position | CY2: Assigned Official | CZ2: Position | DB2: Assigned Official | DC2: Position | DE2: Assigned Official | DF2: Position | DH2: Assigned Official | DI2: Position
AK3: Courtney Fecske | AL3: Chief Referee-SYS | AN3: Daren Patterson | AO3: Chief Referee-SYS | AQ3: Christopher Brunner | AR3: Chief Referee-SYS | AT3: Alyssa Liverette | AU3: Chief Referee-SYS | AW3: Melissa Christensen | AX3: Chief Referee-SYS | AZ3: Richard Perez | BA3: Chief Referee-SYS | BC3: Ann Buckley | BD3: Chief Referee-SYS | BF3: Cheryl Litman | BG3: Chief Referee-SYS | BI3: Devon Hensel | BJ3: Chief Referee-SYS | BL3: Robin Greenleaf | BM3: Chief Referee-SYS | BO3: Carylyn Landt | BP3: Chief Referee-SYS | BR3: Laura Days | BS3: Chief Referee-SYS | BU3: Karin Sherr | BV3: Chief Referee-SYS | BX3: Laura Days | BY3: Chief Referee-SYS | CA3: Hannelore Murphy | CB3: Chief Referee-SYS | CD3: Robin Greenleaf | CE3: Chief Referee-SYS | CG3: Wayne Hundley | CH3: Chief Referee-SYS | CJ3: Robert Bauer | CK3: Chief Referee-SYS | CM3: Daren Patterson | CN3: Assistant Referee-SYS | CP3: Judith Edmunds | CQ3: Assistant Referee-SYS | CS3: Hannelore Murphy | CT3: Chief Referee-SYS | CV3: Richard Perez | CW3: Chief Referee-SYS | CY3: Daren Patterson | CZ3: Chief Referee-SYS | DB3: Alexandra Mahler-Haug | DC3: TS-SYS | DE3: Hazel Wecal | DF3: J-SYS
AK4: Alyssa Liverette | AL4: Assistant Referee-SYS | AQ4: Carylyn Landt | AR4: Assistant Referee-SYS | AW4: Devon Hensel | AX4: Assistant Referee-SYS | AZ4: Rebecca Finder | BA4: Assistant Referee-SYS | BC4: Susan Haugh | BD4: Assistant Referee-SYS | BF4: Daren Patterson | BG4: Assistant Referee-SYS | BI4: Daren Patterson | BJ4: Assistant Referee-SYS | BL4: Richard Perez | BM4: Assistant Referee-SYS | BO4: Cheryl Litman | BP4: Assistant Referee-SYS | BR4: Thomas Sobell | BS4: Assistant Referee-SYS | BU4: Lauren Whittaker | BV4: Assistant Referee-SYS | BX4: Ann Buckley | BY4: Assistant Referee-SYS | CA4: Steve Wolkin | CB4: Assistant Referee-SYS | CD4: Susan Haugh | CE4: Assistant Referee-SYS | CG4: Laura Days | CH4: Assistant Referee-SYS | CJ4: Leonard Colarusso | CK4: Assistant Referee-SYS | CM4: Susan Haugh | CN4: Assistant Referee-SYS | CP4: Ann Fauver | CQ4: Assistant Referee-SYS | CS4: Caren Kirsch | CT4: Assistant Referee-SYS | CV4: Thomas Sobell | CW4: Assistant Referee-SYS | CY4: Robin Greenleaf | CZ4: Assistant Referee-SYS | DB4: Ann Buckley | DC4: J-SYS | DE4: Jo Ann Hall | DF4: J-SYS
AK5: Cassy Papajohn | AL5: Assistant Referee-SYS | AN5: Carolyn Clausius | AO5: Assistant Referee-SYS | AQ5: Mary Ann Wilcox | AR5: Assistant Referee-SYS | AT5: Richard Kern | AU5: Assistant Referee-SYS | AW5: Daren Patterson | AX5: Assistant Referee-SYS | AZ5: Richard Kern | BA5: Assistant Referee-SYS | BC5: Thomas Sobell | BD5: Assistant Referee-SYS | BF5: Lauren Whittaker | BG5: Assistant Referee-SYS | BI5: Steve Wolkin | BJ5: Assistant Referee-SYS | BL5: Steve Wolkin | BM5: Assistant Referee-SYS | BO5: Hannelore Murphy | BP5: Assistant Referee-SYS | BR5: Robin Greenleaf | BS5: Assistant Referee-SYS | BU5: Daren Patterson | BV5: Assistant Referee-SYS | BX5: Judith Edmunds | BY5: Assistant Referee-SYS | CA5: Lois Long | CB5: Assistant Referee-SYS | CD5: Judith Edmunds | CE5: Assistant Referee-SYS | CG5: Hannelore Murphy | CH5: Assistant Referee-SYS | CJ5: Laura Days | CK5: Assistant Referee-SYS | CM5: Hannelore Murphy | CN5: Assistant Referee-SYS | CP5: Laura Days | CQ5: Assistant Referee-SYS | CS5: Richard Perez | CT5: Assistant Referee-SYS | CV5: Laura Days | CW5: Assistant Referee-SYS | CY5: Hannelore Murphy | CZ5: Assistant Referee-SYS | DB5: Ann Fauver | DC5: TC-SYS | DE5: Kristy Panos | DF5: J-SYS
AK6: Susan Haugh | AL6: Assistant Referee-SYS | AN6: Scheherezade Cleveland | AO6: Assistant Referee-SYS | AQ6: Lynn Auxier | AR6: Chief Scoring Official | AT6: Courtney Fecske | AU6: Assistant Referee-SYS | AW6: Lori Osborne | AX6: Assistant Referee-SYS | BC6: Gale Tanger | BD6: Assistant Referee-SYS | BF6: Steve Wolkin | BG6: Assistant Referee-SYS | BI6: Jayne Rendel | BJ6: Chief Accountant | BL6: Judith Edmunds | BM6: Assistant Referee-SYS | BO6: Daren Patterson | BP6: Assistant Referee-SYS | BR6: Richard Perez | BS6: Assistant Referee-SYS | BU6: Hannelore Murphy | BV6: Assistant Referee-SYS | BX6: Ann Fauver | BY6: Assistant Referee-SYS | CA6: Susan Haugh | CB6: Assistant Referee-SYS | CG6: Mary Lou Rothman | CH6: Assistant Referee-SYS | CJ6: Judith Edmunds | CK6: Assistant Referee-SYS | CM6: Lois Long | CN6: Assistant Referee-SYS | CP6: Leonard Colarusso | CQ6: Assistant Referee-SYS | CS6: Steve Wolkin | CT6: Assistant Referee-SYS | CV6: Judith Edmunds | CW6: Assistant Referee-SYS | CY6: Lois Long | CZ6: Assistant Referee-SYS | DB6: Audrey Kamm | DC6: TS-SYS | DE6: Leanne Cluff-Richardson | DF6: J-SYS
AN7: Susan Demeniuk | AO7: Assistant Referee-SYS | AQ7: Christine Hills | AR7: Assistant Scoring Official | AT7: Susan Haugh | AU7: Assistant Referee-SYS | AW7: Christine Hills | AX7: Chief Accountant | BC7: Jennifer Lyon | BD7: Chief Accountant | BF7: Debra Dryburgh | BG7: Chief Accountant | BI7: Valarie Berger | BJ7: Assistant Accountant | BL7: Susan Haugh | BM7: Assistant Referee-SYS | BO7: Valarie Berger | BP7: Chief Accountant | BR7: Lois Long | BS7: Assistant Referee-SYS | BU7: Karen Wolanchuk | BV7: Assistant Referee-SYS | BX7: Jeanette Davey | BY7: TC-SYS | CD7: Daren Patterson | CE7: Assistant Referee-SYS | CG7: Lauren Whittaker | CH7: Assistant Referee-SYS | CJ7: Susan Haugh | CK7: Assistant Referee-SYS | CM7: Steve Wolkin | CN7: Chief Referee-SYS | CO7: I think... | CS7: Daren Patterson | CT7: Assistant Referee-SYS | CV7: Susan Haugh | CW7: Assistant Referee-SYS | CZ7: Assistant Referee-SYS | DB7: Barbara Shostak | DC7: J-SYS | DE7: Mary Ann Wilcox | DF7: J-SYS
AK8: Tricia Privette | AL8: Chief Scoring Official | AN8: Gordon MacKay | AO8: Chief Scoring Official | AQ8: Beth Roberts | AR8: Chief Scoring System Technician | AT8: Lainie DeMore | AU8: Chief Accountant | AW8: Connie Schamaun | AX8: Assistant Accountant | AZ8: Bryan Keller | BA8: Chief Accountant | BC8: Elizabeth Murray | BD8: Assistant Accountant | BF8: Beth Roberts | BG8: Assistant Accountant | BI8: Gay Ann Louiselle | BJ8: Chief Technical Accountant | BL8: Megan Brown | BM8: Chief Accountant | BO8: Michael Meyer | BP8: Assistant Accountant | BR8: Kimberley Moore | BS8: Chief Accountant | BU8: Beth Roberts | BV8: Chief Accountant | BX8: Lauren O'Toole | BY8: TC-SYS | CA8: Carylyn Landt | CB8: TC-SYS | CD8: Lisa Insley | CE8: TC-SYS | CG8: Steve Wolkin | CH8: Assistant Referee-SYS | CJ8: Steve Wolkin | CK8: Assistant Referee-SYS | CM8: Mary Lou Rothman | CN8: Referee | CP8: Carylyn Landt | CQ8: TC-SYS | CS8: Susan McInnes | CT8: TC-SYS | CV8: Ann Fauver | CW8: TC-SYS | CY8: Carylyn Landt | CZ8: TC-SYS | DB8: Elizabeth Barrow | DC8: J-SYS | DE8: Mary Lou Rothman | DF8: J-SYS
AN9: Caryn Bickerstaff | AO9: Assistant Scoring Official | AQ9: Connie Schamaun | AR9: Assistant Scoring System Technician | AT9: Kristin Gordon | AU9: Assistant Accountant | AW9: Calvin Carson | AX9: Chief Technical Accountant | BC9: John Herbert | BD9: Chief Technical Accountant | BF9: Calvin Carson | BG9: Chief Technical Accountant | BI9: Katherine Bosworth | BJ9: Assistant Technical Accountant | BL9: Laura Mitchell | BM9: Assistant Accountant | BO9: E. Michael Elmaleh | BP9: Chief Technical Accountant | BR9: Joanne Nipple | BS9: Assistant Accountant | BU9: Rodney Williams | BV9: Assistant Accountant | BX9: Erin Bridge | BY9: TS-SYS | CA9: Richard Perez | CB9: TC-SYS | CD9: Lauren O'Toole | CE9: TC-SYS | CG9: Jeanette Davey | CH9: TC-SYS | CJ9: Ann Buckley | CK9: Judge-SYS | CM9: Rebecca Finder | CN9: Judge-SYS | CP9: Jeanette Davey | CQ9: TC-SYS | CS9: Dann Krueger | CT9: TC-SYS | CV9: Matthew O'Toole | CW9: TC-SYS | CY9: Susan McInnes | CZ9: TC-SYS | DB9: Erin Bridge | DC9: TS-SYS | DE9: Pamela Pangle | DF9: J-SYS
AN10: Elizabeth Harty | AO10: Chief Scoring System Technician | AQ10: Pamela Dawson-LeMarr | AR10: Chief Music Coordinator | AT10: Laura Mitchell | AU10: Chief Technical Accountant | AW10: Jay Michael | AX10: Assistant Technical Accountant | BC10: Alan Heinold | BD10: Assistant Technical Accountant | BF10: Gordon MacKay | BG10: Assistant Technical Accountant | BI10: April Zak | BJ10: Chief Music Coordinator | BL10: Alan Heinold | BM10: Chief Technical Accountant | BO10: Beth Roberts | BP10: Assistant Technical Accountant | BR10: Michael Rowland | BS10: Assistant Accountant | BU10: Connie Schamaun | BV10: Assistant Accountant | BX10: Melissa Christensen | BY10: TS-SYS | CA10: Summer Nagy | CB10: TS-SYS | CD10: Kristin Abbott | CE10: TS-SYS | CG10: Carylyn Landt | CH10: TC-SYS | CJ10: Richard Perez | CK10: Judge-SYS | CM10: Leanne Cluff-Richardson | CN10: Judge-SYS | CP10: Elizabeth Lee | CQ10: TS-SYS | CS10: Carolyn Drzewiecki | CT10: TS-SYS | CV10: Martha Buckley | CW10: TS-SYS | CY10: Erin Bridge | CZ10: TS-SYS | DB10: Hannelore Murphy | DC10: R-SYS | DE10: Rita Cerny | DF10: J-SYS
AK11: Michelle Cohen | AL11: Assistant Scoring Official | AN11: Jay Michael | AO11: Assistant Scoring System Technician | AQ11: Susan Miller | AR11: Assistant Music | AT11: John Herbert | AU11: Assistant Technical Accountant | AW11: Harley Johnson | AX11: Chief Music Coordinator | AZ11: Veronica Nebb | BA11: Chief Technical Accountant | BC11: Paul Crugnola | BD11: Chief Music Coordinator | BF11: Pamela Dawson-LeMarr | BG11: Chief Music Coordinator | BI11: Miranda Young | BJ11: Assistant Music | BL11: John Herbert | BM11: Assistant Technical Accountant | BO11: Jim Carlisle | BP11: Chief Music Coordinator | BR11: Alan Heinold | BS11: Chief Technical Accountant | BU11: Calvin Carson | BV11: Assistant Accountant | BX11: Felicia Haining-Miller | BY11: TS-SYS | CA11: Lauren Bracken | CB11: TS-SYS | CD11: Lauren Bracken | CE11: TS-SYS | CG11: Erin Bridge | CH11: TS-SYS | CJ11: Jeanette Davey | CK11: Judge-SYS | CM11: Charles Cope | CN11: Judge-SYS | CP11: Cathleen Renzi | CQ11: TS-SYS | CS11: Audrey Kamm | CT11: TS-SYS | CV11: Devon Hensel | CW11: TS-SYS | CY11: Elizabeth Lee | CZ11: TS-SYS | DB11: Judith Edmunds | DC11: R-SYS | DE11: Steve Wolkin | DF11: J-SYS
AK12: Alan Heinold | AL12: Chief Scoring System Technician | AN12: Tony Chaouch | AO12: Chief Music Coordinator | AQ12: Nathan Meyers | AR12: Chief Announcer | AT12: Paul Crugnola | AU12: Chief Music Coordinator | AW12: Jim Carlisle | AX12: Assistant Music | AZ12: David Hopson | BA12: Assistant Technical Accountant | BC12: Marilyn Nolte | BD12: Assistant Music | BF12: David Bakke | BG12: Assistant Music | BI12: Jeff Rendel | BJ12: Chief Announcer | BL12: Mathew Hough | BM12: Chief Music Coordinator | BO12: Jay Michael | BP12: Assistant Music | BR12: Cathy Brinkman | BS12: Assistant Technical Accountant | BU12: Jack Vest | BV12: Chief Technical Accountant | BX12: Lisa Insley | BY12: TS-SYS | CA12: Audrey Kamm | CB12: TS-SYS | CD12: Martha Buckley | CE12: TS-SYS | CG12: Carolyn Drzewiecki | CH12: TS-SYS | CJ12: Devon Hensel | CK12: Judge-SYS | CM12: Carylyn Landt | CN12: Judge-SYS | CP12: Ashleigh Renard | CQ12: TS-SYS | CS12: Felicia Haining-Miller | CT12: TS-SYS | CV12: Megan Jackson | CW12: TS-SYS | CY12: Audrey Kamm | CZ12: TS-SYS | DB12: Laura Days | DC12: R-SYS | DE12: Lois Long | DF12: R-SYS
AK13: E. Michael Elmaleh | AL13: Assistant Scoring System Technician | AN13: Harley Johnson | AO13: Assistant Music | AT13: Juan Rios | AU13: Assistant Music | AW13: Brian Peltz | AX13: Chief Announcer | AZ13: Nancy Ginkus-O'Connor | BA13: Chief Music Coordinator | BC13: David Magill | BD13: Chief Announcer | BF13: Timothy Rinkel | BG13: Chief Announcer | BI13: Rebecca Finder | BJ13: TC-SYS | BL13: James Chen | BM13: Assistant Music | BO13: Marc DeContreaus | BP13: Chief Announcer | BR13: Susan LaLone | BS13: Chief Music Coordinator | BU13: Thomas Tanger | BV13: Assistant Technical Accountant | BX13: Andrew Lam | BY13: Data-SYS | CA13: Ellie Nielsen | CB13: TS-SYS | CD13: Summer Nagy | CE13: TS-SYS | CG13: Felicia Haining-Miller | CH13: TS-SYS | CJ13: Dann Krueger | CK13: Judge-SYS | CM13: Wayne Hundley | CN13: Judge-SYS | CP13: Lauren O'Toole | CQ13: TS-SYS | CS13: Rachael Naphtal Einstein | CT13: TS-SYS | CV13: Cathleen Renzi | CW13: TS-SYS | CY13: Kelley Ristau | CZ13: TS-SYS | DB13: Lauren O'Toole | DC13: TS-SYS | DE13: Susan Haugh | DF13: R-SYS
AK14: Susan LaLone | AL14: Chief Music Coordinator | AN14: Ellen Sendelbach | AO14: Chief Announcer | AT14: Lisa Gentile | AU14: Chief Announcer | AZ14: Hayley Leonard | BA14: Assistant Music | BC14: Rachael Naphtal Einstein | BD14: TC-SYS | BF14: Carylyn Landt | BG14: TC-SYS | BL14: Susan LaLone | BM14: Assistant Music | BO14: Laura Days | BP14: TC-SYS | BR14: Paul Crugnola | BS14: Assistant Music | BU14: Jim Carlisle | BV14: Chief Music Coordinator | CB14: Data-SYS | CD14: Cathleen Renzi | CE14: TS-SYS | CG14: Devon Hensel | CH14: TS-SYS | CJ14: Nancy Marron-Asti | CK14: Judge-SYS | CM14: Hazel Wecal | CN14: Judge-SYS | CP14: William Beharrell | CQ14: Data-SYS | CS14: Krisin Abbott | CT14: Data-SYS | CV14: Thomas Tanger | CW14: Data-SYS | CZ14: Data-SYS | DB14: Leonard Colarusso | DC14: R-SYS | DE14: Carylyn Landt | DF14: J-SYS
AZ15: Lexi Rohner | BA15: Chief Announcer | BC15: Robin Greenleaf | BD15: TC/J-SYS | BF15: Megan Jackson | BG15: TC-SYS | BI15: Kristi King | BJ15: TS-SYS | BL15: Robert Stosse | BM15: Chief Announcer | BO15: Rebecca Finder | BP15: TC-SYS | BR15: Loris Chen | BS15: Chief Announcer | BU15: JoAnn Eastman | BV15: Assistant Music | BX15: Michele Blatt | BY15: Judge-SYS | CG15: Elizabeth Harty | CH15: Data-SYS | CJ15: Rachael Naphtal Einstein | CK15: Judge-SYS | CM15: Elizabeth Harty | CN15: Judge-SYS | CP15: Sharon Watson | CQ15: Judge-SYS | CS15: Rita Cerny | CT15: Judge-SYS | CV15: Michele Blatt | CW15: Judge-SYS | CY15: Pamela Pangle | CZ15: Judge-SYS | DB15: Lisa Insley | DC15: J-SYS | DE15: Charles Cope | DF15: J-SYS
AK16: James Chen | AL16: Assistant Music | AQ16: Susan McInnes | AR16: TC-SYS | BC16: Laura Days | BD16: TC-SYS | BF16: Zeynep Aydin Mayerle | BG16: TS-SYS | BI16: Summer Nagy | BJ16: TS-SYS | BL16: Rachael Naphtal Einstein | BM16: TC/J-SYS | BO16: Summer Nagy | BP16: TS-SYS | BU16: William Goen | BV16: Assistant Music | BX16: Devon Hensel | BY16: Judge-SYS | CA16: Karin Sherr | CB16: Judge-SYS | CD16: Ann Buckley | CE16: Judge-SYS | CG16: Charles Cope | CH16: Judge-SYS | CJ16: Deveny Deck | CK16: Judge-SYS | CM16: Suzanne Ferguson | CN16: Judge-SYS | CP16: Matthew O'Toole | CQ16: Judge-SYS | CS16: Charles Cope | CT16: Judge-SYS | CV16: Ann Buckley | CW16: Judge-SYS | CY16: Lauren O'Toole | CZ16: Judge-SYS | DB16: Martha Rasmussen | DC16: J-SYS | DE16: Dorothy Tank | DF16: J-SYS
AK17: Katherine Huang | AL17: Chief Announcer | AQ17: Laura Days | AR17: TC-SYS | AW17: Audrey Kamm | AX17: TC-SYS | BC17: Caitlin Gallagher | BD17: TS-SYS | BF17: Taylor Galarnyk Hill | BG17: TS-SYS | BI17: Lauren Bracken | BJ17: TS-SYS | BL17: Matthew O'Toole | BM17: TC-SYS | BO17: Carolyn Drzewiecki | BP17: TS-SYS | BU17: Juan Rios | BV17: Assistant Music | BX17: Caren Kirsch | BY17: Judge-SYS | CA17: Stephanie Pusch | CB17: Judge-SYS | CD17: Ann Fauver | CE17: Judge-SYS | CG17: Susan Demeniuk | CH17: Judge-SYS | CJ17: Lauren O'Toole | CK17: Judge-SYS | CM17: Tiffani Shipley | CN17: Judge-SYS | CP17: Ann Buckley | CQ17: Judge-SYS | CS17: Suzanne Ferguson | CT17: Judge-SYS | CV17: Leonard Colarusso | CW17: Judge-SYS | CY17: Dann Krueger | CZ17: Judge-SYS | DB17: Mary-Elizabeth Wightman | DC17: J-SYS | DE17: Elizabeth Barrow | DF17: J-SYS
AN18: Dann Krueger | AO18: TC-SYS | AQ18: Morgan Sterns | AR18: TS-SYS | AT18: Martha Buckley | AU18: TC-SYS | AW18: Melissa Christensen | AX18: TC-SYS | BC18: Lauren Neidig | BD18: TS-SYS | BF18: Ellie Nielsen | BG18: TS-SYS | BI18: Kristen Belcourt | BJ18: Data-SYS | BL18: Caitlin Gallagher | BM18: TS-SYS | BO18: Kristin D'Antonio | BP18: TS-SYS | BU18: Timothy Rinkel | BV18: Chief Announcer | BX18: Cheryl Litman | BY18: Judge-SYS | CA18: Mary Lou Rothman | CB18: Judge-SYS | CD18: Barbara Shostak | CE18: Judge-SYS | CG18: Lois Long | CH18: Judge-SYS | CJ18: Stephanie Pusch | CK18: Judge-SYS | CM18: Mary Ann Wilcox | CN18: Judge-SYS | CP18: Lisa Insley | CQ18: Judge-SYS | CS18: Elizabeth Harty | CT18: Judge-SYS | CV18: Laura Gund | CW18: Judge-SYS | CY18: Tiffani Shipley | CZ18: Judge-SYS | DB18: Matthew O'Toole | DC18: J-SYS | DE18: Caren Kirsch | DF18: R-SYS
AN19: Martha Buckley | AO19: TC-SYS | AQ19: Zeynep Aydin Mayerle | AR19: TS-SYS | AW19: Taylor Galarnyk Hill | AX19: TS-SYS | AZ19: Carylyn Landt | BA19: TC-SYS | BF19: Kristin D'Antonio | BG19: TS-SYS | BI19: Karen Anderson | BJ19: Data-SYS | BL19: Cathleen Renzi | BM19: TS-SYS | BO19: Felicia Haining-Miller | BP19: TS-SYS | BR19: Lauren O'Toole | BS19: TC-SYS | BU19: Susan McInnes | BV19: TC-SYS | BX19: Alyssa Liverette | BY19: Judge-SYS | CA19: Lynn Eisenhour | CB19: Judge-SYS | CD19: Cheryl Litman | CE19: Judge-SYS | CG19: Susan McInnes | CH19: Judge-SYS | CJ19: Elliot Schwartz | CK19: Judge-SYS | CM19: Kristy Kasapis | CN19: Judge-SYS | CP19: Elliot Schwartz | CQ19: Judge-SYS | CS19: Hazel Wecal | CT19: Judge-SYS | CV19: Cheryl Litman | CW19: Judge-SYS | CY19: Lauren Whittaker | CZ19: Judge-SYS | DB19: Michele Blatt | DC19: J-SYS | DE19: Daren Patterson | DF19: R-SYS
AN20: Eman Noel Donaire | AO20: TS-SYS | AQ20: Ellie Nielsen | AR20: TS-SYS | AT20: Lisa Insley | AU20: TC-SYS | AW20: Caitlin Gallagher | AX20: TS-SYS | BC20: Cathleen Renzi | BD20: TS-SYS | BF20: Reed Hastings | BG20: Data-SYS | BI20: Lori Osborne | BJ20: Judge-SYS | BL20: Lauren Neidig | BM20: TS-SYS | BO20: Elizabeth Harty | BP20: Data-SYS | BR20: Rachael Naphtal Einstein | BS20: TC-SYS | BU20: Carylyn Landt | BV20: TC-SYS | BX20: Alexandra Mahler-Haug | BY20: Judge-SYS | CA20: Hazel Wecal | CB20: Judge-SYS | CG20: Rachael Naphtal Einstein | CH20: Judge-SYS | CJ20: Barbara Shostak | CK20: Judge-SYS | CM20: Sharon Watson | CN20: Judge-SYS | CP20: Shirley Holdsworth | CQ20: Judge-SYS | CS20: Lauren Whittaker | CT20: Judge-SYS | CV20: Patricia Lynch | CW20: Judge-SYS | CY20: Mary Ann Wilcox | CZ20: Judge-SYS | DB20: Patricia Lynch | DC20: J-SYS | DE20: Hannelore Murphy | DF20: R-SYS
AK21: Cathleen Renzi | AL21: TC-SYS | AN21: Summer Nagy | AO21: TS-SYS | AQ21: William Rowe | AR21: Data-SYS | AT21: Lisa Insley | AU21: Judge-SYS | AW21: Kristin D'Antonio | AX21: TS-SYS | AZ21: Laura Days | BA21: TC-SYS | BC21: Elliot Schwartz | BD21: Data-SYS | BF21: Jessica Melton | BG21: Data-SYS | BI21: Sharon Watson | BJ21: Judge-SYS | BL21: Martha Buckley | BM21: TS-SYS | BO21: Laura Patterson | BP21: Data-SYS | BR21: Melissa Christensen | BS21: TS-SYS | BU21: Lauren Bracken | BV21: TS-SYS | BX21: William Mein | BY21: Judge-SYS | CA21: Pamela Pangle | CB21: Judge-SYS | CD21: Courtney Fecske | CE21: Judge-SYS | CG21: Pamela Pangle | CH21: Judge-SYS | CJ21: Matthew O'Toole | CK21: TC-SYS | CM21: Jennifer Simon | CN21: Judge-SYS | CP21: Rebecca Finder | CQ21: Judge-SYS | CS21: Pamela Pangle | CT21: Judge-SYS | CV21: Rachael Naphtal Einstein | CW21: Judge-SYS | CY21: Charles Cope | CZ21: Judge-SYS | DB21: Robin Greenleaf | DC21: TC-SYS | DE21: Dann Krueger | DF21: TC-SYS
AN22: Kristin D'Antonio | AO22: TS-SYS | AT22: Eman Noel Donaire | AU22: TS-SYS | AW22: Melissa Delano | AX22: TS-SYS | AZ22: Morgan Sterns | BA22: TS-SYS | BC22: Robin Greenleaf | BD22: Judge/TC-SYS | BF22: Susan Demeniuk | BG22: Judge-SYS | BI22: Tiffani Shipley | BJ22: Judge-SYS | BL22: Elliot Schwartz | BM22: Data-SYS | BO22: Lynn Eisenhour | BP22: Judge-SYS | BR22: Martha Buckley | BS22: TS-SYS | BU22: Summer Nagy | BV22: TS-SYS | BX22: Matthew O'Toole | BY22: Judge-SYS | CA22: Lauren Whittaker | CB22: Judge-SYS | CG22: Stephanie Pusch | CH22: Judge-SYS | CJ22: Ann Fauver | CK22: TC-SYS | CP22: Thomas Sobell | CQ22: Judge-SYS | CS22: Carla Golubski | CT22: Judge-SYS | CV22: Elliot Schwartz | CW22: Judge-SYS | CY22: Lisa Insley | CZ22: Judge-SYS | DB22: Sara Jayne Stephens | DC22: J-SYS | DE22: Jeanette Davey | DF22: TC-SYS
AK23: Carylyn Landt | AL23: TC-SYS | AN23: Taylor Galarnyk Hill | AO23: TS-SYS | AT23: Tessa Lytle | AU23: TS-SYS | AW23: Lisa Landon | AX23: Data-SYS | AZ23: Zeynep Aydin Mayerle | BA23: TS-SYS | BC23: Rachael Naphtal Einstein | BD23: Judge/TC-SYS | BF23: Carolyn Clausius | BG23: Judge-SYS | BI23: Carylyn Landt | BJ23: Judge-SYS | BL23: Megan Jackson | BM23: Data-SYS | BO23: Audrey Kamm | BP23: TC/J-SYS | BR23: Cathleen Renzi | BS23: TS-SYS | BU23: Audrey Kamm | BV23: TS-SYS | BX23: Scheherezade Cleveland | BY23: Judge-SYS | CA23: Daren Patterson | CB23: Judge-SYS | CG23: Elliot Schwartz | CH23: Judge-SYS | CJ23: Martha Buckley | CK23: TS-SYS | CM23: Gale Tanger | CN23: TC-SYS | CP23: Nancy Marron-Asti | CQ23: Judge-SYS | CS23: Dorothy Tank | CT23: Judge-SYS | CV23: Barbara Shostak | CW23: Judge-SYS | CY23: Susan Demeniuk | CZ23: Judge-SYS | DB23: Shirley Holdsworth | DC23: J-SYS | DE23: Devon Hensel | DF23: TS-SYS
AK24: Lisa Insley | AL24: TS-SYS | AN24: Stephanie Lab | AO24: Data-SYS | AQ24: Stephanie Pusch | AR24: Data-SYS | AT24: Lauren Neidig | AU24: TS-SYS | AW24: Elizabeth Harty | AX24: Data-SYS | AZ24: Summer Nagy | BA24: TS-SYS | BC24: Richard Kern | BD24: Judge-SYS | BF24: Pamela Pangle | BG24: Judge-SYS | BI24: Irrit Mihok | BJ24: Judge-SYS | BL24: Rachael Naphtal Einstein | BM24: Judge/TC-SYS | BO24: Scheherezade Cleveland | BP24: Judge-SYS | BR24: Kelley Ristau | BS24: TS-SYS | BU24: Ellie Nielsen | BV24: TS-SYS | BX24: Elliot Schwartz | BY24: Judge-SYS | CA24: Mary Ann Wilcox | CB24: Judge-SYS | CD24: Matthew O'Toole | CE24: Judge-SYS | CG24: Tiffani Shipley | CH24: Judge-SYS | CJ24: Erin Bridge | CK24: TS-SYS | CM24: Jeanette Davey | CN24: TC-SYS | CP24: Michele Blatt | CQ24: Judge-SYS | CS24: Tiffani Shipley | CT24: Judge-SYS | CV24: Jo Ann Hall | CW24: Judge-SYS | CY24: Mary Lou Rothman | CZ24: Judge-SYS | DB24: Susan Haugh | DC24: R-SYS | DE24: Felicia Haining-Miller | DF24: TS-SYS
AK25: Melissa Christensen | AL25: TS-SYS | AN25: Elliot Schwartz | AO25: Data-SYS | AQ25: Irrit Mihok | AR25: Judge-SYS | AW25: Felicia Haining-Miller | AX25: Judge-SYS | AZ25: Jennifer Simon | BA25: Data-SYS | BC25: Kendra Wright | BD25: Judge-SYS | BF25: Richard Kern | BG25: Judge-SYS | BL25: Lauren O'Toole | BM25: Judge-SYS | BO25: Devon Hensel | BP25: Judge-SYS | BR25: Andrew Lam | BS25: Data-SYS | BU25: Scheherezade Cleveland | BV25: Data-SYS | BX25: Sara Jayne Stephens | BY25: Judge-SYS | CA25: Rebecca Finder | CB25: Judge-SYS | CD25: Megan Jackson | CE25: Judge-SYS | CG25: Jennifer Simon | CH25: Judge-SYS | CJ25: Summer Nagy | CK25: TS-SYS | CM25: Lauren Bracken | CN25: TS-SYS | CP25: Barbara Shostak | CQ25: Judge-SYS | CS25: Mary Lou Rothman | CT25: Judge-SYS | CV25: Mary-Elizabeth Wightman | CW25: Judge-SYS | CY25: Sharon Watson | CZ25: Judge-SYS | DB25: William Beharrell | DC25: R-SYS | DE25: Lisa Insley | DF25: TS-SYS
AK26: Caitlin Gallagher | AL26: TS-SYS | AN26: Lori Osborne | AO26: Judge-SYS | AQ26: Rebecca Ye | AR26: Judge-SYS | AT26: Kristi King | AU26: TS-SYS | AZ26: Dana Hordyszynski | BA26: Data-SYS | BC26: Melissa Christensen | BD26: Judge-SYS | BF26: Stephanie Pusch | BG26: Judge-SYS | BI26: Mary Ann Wilcox | BJ26: Judge-SYS | BL26: Sharon Watson | BM26: Judge-SYS | BO26: Richard Kern | BP26: Judge-SYS | BR26: Mary-Elizabeth Wightman | BS26: Data-SYS | BU26: Robert Withrow | BV26: Data-SYS | BX26: Mary-Elizabeth Wightman | BY26: Judge-SYS | CA26: Courtney Fecske | CB26: Judge-SYS | CD26: Paula Ziegler | CE26: Judge-SYS | CG26: Sharon Watson | CH26: Judge-SYS | CJ26: Megan Jackson | CK26: TS-SYS | CM26: Audrey Kamm | CN26: TS-SYS | CP26: Dennis Morrill | CQ26: Judge-SYS | CS26: Mary Ann Wilcox | CT26: Judge-SYS | CV26: Rebecca Finder | CW26: Judge-SYS | CY26: Hazel Wecal | CZ26: Judge-SYS | DB26: William Mein | DC26: J-SYS | DE26: Melissa Delano | DF26: TS-SYS
AK27: Samantha Goldberg | AL27: TS-SYS | AN27: Lorrie Parker | AO27: Judge-SYS | AQ27: Rebecca Finder | AR27: Judge-SYS | AT27: Anthony Iarriccio | AU27: Data-SYS | AW27: Pamela Pangle | AX27: Judge-SYS | AZ27: Rebecca Ye | BA27: Judge-SYS | BC27: Rebecca Ye | BD27: Judge-SYS | BF27: Elise Requadt | BG27: Judge-SYS | BI27: Michael Bauer | BJ27: Judge-SYS | BL27: Cheryl Litman | BM27: Judge-SYS | BO27: Christine Magill | BP27: Judge-SYS | CA27: Barbara Shostak | CB27: Judge-SYS | CD27: Suzanne Ferguson | CE27: Judge-SYS | CG27: Hazel Wecal | CH27: Judge-SYS | CJ27: Cheryl Litman | CK27: Data-SYS | CM27: Alexandra Mahler-Haug | CN27: TS-SYS | CP27: Jo Ann Hall | CQ27: Judge-SYS | CS27: Cheryl Litman | CT27: Judge-SYS | CV27: Carla Golubski | CW27: Judge-SYS | CY27: Caren Kirsch | CZ27: Judge-SYS | DB27: Hannelore Murphy | DC27: J-SYS | DE27: Lois Long | DF27: J-SYS
AK28: Tom Richardson | AL28: Data-SYS | AN28: April Zak | AO28: Judge-SYS | AQ28: Richard Perez | AR28: Judge-SYS | AT28: Cheryl Litman | AU28: Data-SYS | AW28: Courtney Fecske | AX28: Judge-SYS | AZ28: Tiffani Shipley | BA28: Judge-SYS | BC28: Alyssa Liverette | BD28: Judge-SYS | BF28: Elizabeth Harty | BG28: Judge-SYS | BI28: Carla Golubski | BJ28: Judge-SYS | BL28: Melissa Christensen | BM28: Judge-SYS | BO28: Pamela Pangle | BP28: Judge-SYS | BR28: Michele Blatt | BS28: Judge-SYS | BU28: Courtney Fecske | BV28: Judge-SYS | CD28: Dennis Morrill | CE28: Judge-SYS | CG28: Mary Ann Wilcox | CH28: Judge-SYS | CM28: Elizabeth Lee | CN28: TS-SYS | CP28: William Mein | CQ28: Judge-SYS | CV28: Ann Fauver | CW28: Judge-SYS | DB28: Laura Days | DC28: J-SYS | DE28: Susan Haugh | DF28: J-SYS
AN29: Kendra Wright | AO29: Judge-SYS | AQ29: Sharon Watson | AR29: Judge-SYS | AW29: Alyssa Liverette | AX29: Judge-SYS | AZ29: April Zak | BA29: Judge-SYS | BC29: Mary-Elizabeth Wightman | BD29: Judge-SYS | BF29: Richard Perez | BG29: Judge-SYS | BI29: Carylyn Landt | BJ29: TC-SYS | BL29: Alyssa Liverette | BM29: Judge-SYS | BO29: Kristen Belcourt | BP29: Judge-SYS | BR29: Ann Buckley | BS29: Judge-SYS | BU29: Tiffani Shipley | BV29: Judge-SYS | CD29: Michele Blatt | CE29: Judge-SYS | CM29: David Santee | CN29: Data-SYS | DB29: Leonard Colarusso | DC29: J-SYS
AN30: Gale Tanger | AO30: Judge-SYS | AT30: Christine Magill | AU30: Judge-SYS | AW30: Irrit Mihok | AX30: Judge-SYS | AZ30: Mary Ann Wilcox | BA30: Judge-SYS | BC30: Colette Nygren | BD30: Judge-SYS | BF30: Christine Magill | BG30: Judge-SYS | BI30: Kristen Belcourt | BJ30: Judge-SYS | BL30: Gale Tanger | BM30: Judge-SYS | BO30: April Zak | BP30: Judge-SYS | BR30: Lynn Eisenhour | BS30: Judge-SYS | BU30: Mary Ann Wilcox | BV30: Judge-SYS | CD30: Nancy Marron-Asti | CE30: Judge-SYS | CJ30: Nancy Marron-Asti | CK30: Judge-SYS
AN31: Christine Magill | AO31: Judge-SYS | AQ31: Pamela Pangle | AR31: Judge-SYS | AT31: Laura Days | AU31: Judge-SYS | AW31: Cassy Papajohn | AX31: Judge-SYS | AZ31: Sharon Watson | BA31: Judge-SYS | BC31: Lauren Whittaker | BD31: Judge-SYS | BF31: Courtney Fecske | BG31: Judge-SYS | BL31: Lisa Insley | BM31: Judge-SYS | BO31: Courtney Fecske | BP31: Judge-SYS | BR31: Susan Haugh | BS31: Judge-SYS | BU31: Rebecca Finder | BV31: Judge-SYS | CD31: Rebecca Finder | CE31: Judge-SYS
AQ32: Katherine Sachs | AR32: Judge-SYS | AW32: Mary-Elizabeth Wightman | AX32: Judge-SYS | AZ32: Michael Bauer | BA32: Judge-SYS | BC32: Deveny Deck | BD32: Judge-SYS | BF32: Audrey Kamm | BG32: Judge-SYS | BL32: Deveny Deck | BM32: Judge-SYS | BO32: Mary Ann Wilcox | BP32: Judge-SYS | BR32: Colette Nygren | BS32: Judge-SYS | BU32: Alyssa Liverette | BV32: Judge-SYS
AK33: Deborah Spence | AL33: Data-SYS | AQ33: Paula Ziegler | AR33: Judge-SYS | AT33: Lynn Eisenhour | AU33: Judge-SYS | AW33: Deveny Deck | AX33: Judge-SYS | AZ33: Carla Golubski | BA33: Judge-SYS | BC33: Scheherezade Cleveland | BD33: Judge-SYS | BF33: Megan Jackson | BG33: Judge-SYS | BL33: Ann Buckley | BM33: Judge-SYS | BO33: Susan Demeniuk | BP33: Judge-SYS | BR33: Elliot Schwartz | BS33: Judge-SYS | BU33: Susan Demeniuk | BV33: Judge-SYS
AK34: Kristen Belcourt | AL34: Judge-SYS | AN34: Richard Kern | AO34: Judge-SYS | AQ34: Tiffani Shipley | AR34: Judge-SYS | AZ34: Christine Magill | BA34: Judge-SYS | BC34: Lisa Insley | BD34: Judge-SYS | BL34: Elise Requadt | BM34: Judge-SYS | BR34: Mary Lou Rothman | BS34: Judge-SYS | BU34: Devon Hensel | BV34: Judge-SYS
AK35: Andrew Lam | AL35: Judge-SYS | AQ35: Susan McInnes | AR35: TS-SYS | AT35: Kendra Wright | AU35: Judge-SYS | AW35: Scheherezade Cleveland | AX35: Judge-SYS | BC35: Rachael Naphtal Einstein | BD35: TS-SYS | BL35: Ann Fauver | BM35: Judge-SYS | BR35: Sara Jayne Stephens | BS35: Judge-SYS | BU35: Carla Golubski | BV35: Judge-SYS
AT36: Paula Ziegler | AU36: Judge-SYS | AW36: Amanda Behen | AX36: Judge-SYS | BL36: Lisa Insley | BM36: TC-SYS | BR36: Barbara Shostak | BS36: Judge-SYS | BU36: Carolyn Clausius | BV36: Judge-SYS
AK37: Lynn Eisenhour | AL37: Judge-SYS | AN37: Michael Bauer | AO37: Judge-SYS | AT37: Elliot Schwartz | AU37: Judge-SYS | AW37: Susan Demeniuk | AX37: Judge-SYS | BL37: Megan Jackson | BM37: TS-SYS | BR37: Matthew O'Toole | BS37: Judge-SYS | BU37: Stephanie Pusch | BV37: Judge-SYS
AK38: Tessa Lytle | AL38: Judge-SYS | AN38: Felicia Haining-Miller | AO38: Judge-SYS | AT38: Christopher Brunner | AU38: Judge-SYS | BU38: Cheryl Litman | BV38: Judge-SYS
BR39: Steve Wolkin | BS39: Judge-SYS | BU39: Pamela Pangle | BV39: Judge-SYS
AN40: Erin Bold | AO40: Judge-SYS | AT40: Meghan Lapointe | AU40: Judge-SYS
...

Sheet Sheet2
A1: Robert Bauer | B1: Erin Bridge | C1: Ann Buckley | D1: Martha Buckley | E1: Leonard Colarusso | F1: Jeanette Davey | G1: Laura Days | H1: Deveny Deck | I1: Judith Edmunds | J1: Ann Fauver | K1: Susan Haugh | L1: Devon Hensel | M1: Megan Walsh Jackson | N1: Dann Krueger | O1: Cheryl Litman | P1: Nancy Marron-Asti | Q1: Summer Nagy | R1: Rachael Naphtal | S1: Lauren O'Toole | T1: Matthew O'Toole | U1: Richard Perez | V1: Stephanie Pusch | W1: Elliot Schwartz | X1: Barbara Shostak | Y1: Steve Wolkin
A3: Robert Bauer | B3: =COUNTIF(Sheet1!CJ:CJ,Sheet2!C3) -> 1 | C3: =TRIM(A3) -> Robert Bauer
A4: Erin Bridge | B4: =COUNTIF(Sheet1!CJ:CJ,Sheet2!C4) -> 1 | C4: =TRIM(A4) -> Erin Bridge
A5: Ann Buckley | B5: =COUNTIF(Sheet1!CJ:CJ,Sheet2!C5) -> 1 | C5: =TRIM(A5) -> Ann Buckley
A6: Martha Buckley | B6: =COUNTIF(Sheet1!CJ:CJ,Sheet2!C6) -> 1 | C6: =TRIM(A6) -> Martha Buckley
A7: Leonard Colarusso | B7: =COUNTIF(Sheet1!CJ:CJ,Sheet2!C7) -> 1 | C7: =TRIM(A7) -> Leonard Colarusso
A8: Jeanette Davey | B8: =COUNTIF(Sheet1!CJ:CJ,Sheet2!C8) -> 1 | C8: =TRIM(A8) -> Jeanette Davey
A9: Laura Days | B9: =COUNTIF(Sheet1!CJ:CJ,Sheet2!C9) -> 1 | C9: =TRIM(A9) -> Laura Days
A10: Deveny Deck | B10: =COUNTIF(Sheet1!CJ:CJ,Sheet2!C10) -> 1 | C10: =TRIM(A10) -> Deveny Deck
A11: Judith Edmunds | B11: =COUNTIF(Sheet1!CJ:CJ,Sheet2!C11) -> 1 | C11: =TRIM(A11) -> Judith Edmunds
A12: Ann Fauver | B12: =COUNTIF(Sheet1!CJ:CJ,Sheet2!C12) -> 1 | C12: =TRIM(A12) -> Ann Fauver
A13: Susan Haugh | B13: =COUNTIF(Sheet1!CJ:CJ,Sheet2!C13) -> 1 | C13: =TRIM(A13) -> Susan Haugh
A14: Devon Hensel | B14: =COUNTIF(Sheet1!CJ:CJ,Sheet2!C14) -> 1 | C14: =TRIM(A14) -> Devon Hensel
... A27: Steve Wolkin | B27: =COUNTIF(Sheet1!CJ:CJ,Sheet2!C27) -> 1 | C27: =TRIM(A27) -> Steve Wolkin
